No ISO: Others
No ISO: Cruise Ship
No ISO: Gambia, The
No ISO: Bahamas, The
No ISO: Cape Verde
No ISO: East Timor
No ISO: Syria
No ISO: Laos
No ISO: Diamond Princess
No ISO: West Bank and Gaza
No ISO: Burma
No ISO: MS Zaandam
Traceback (most recent call last):
  File "/Library/Frameworks/Python.framework/Versions/3.7/lib/python3.7/site-packages/urllib3/contrib/pyopenssl.py", line 485, in wrap_socket
    cnx.do_handshake()
  File "/Library/Frameworks/Python.framework/Versions/3.7/lib/python3.7/site-packages/OpenSSL/SSL.py", line 1915, in do_handshake
    self._raise_ssl_error(self._ssl, result)
  File "/Library/Frameworks/Python.framework/Versions/3.7/lib/python3.7/site-packages/OpenSSL/SSL.py", line 1639, in _raise_ssl_error
    raise SysCallError(errno, errorcode.get(errno))
OpenSSL.SSL.SysCallError: (54, 'ECONNRESET')

During handling of the above exception, another exception occurred:

Traceback (most recent call last):
  File "/Library/Frameworks/Python.framework/Versions/3.7/lib/python3.7/site-packages/urllib3/connectionpool.py", line 672, in urlopen
    chunked=chunked,
  File "/Library/Frameworks/Python.framework/Versions/3.7/lib/python3.7/site-packages/urllib3/connectionpool.py", line 376, in _make_request
    self._validate_conn(conn)
  File "/Library/Frameworks/Python.framework/Versions/3.7/lib/python3.7/site-packages/urllib3/connectionpool.py", line 994, in _validate_conn
    conn.connect()
  File "/Library/Frameworks/Python.framework/Versions/3.7/lib/python3.7/site-packages/urllib3/connection.py", line 394, in connect
    ssl_context=context,
  File "/Library/Frameworks/Python.framework/Versions/3.7/lib/python3.7/site-packages/urllib3/util/ssl_.py", line 370, in ssl_wrap_socket
    return context.wrap_socket(sock, server_hostname=server_hostname)
  File "/Library/Frameworks/Python.framework/Versions/3.7/lib/python3.7/site-packages/urllib3/contrib/pyopenssl.py", line 491, in wrap_socket
    raise ssl.SSLError("bad handshake: %r" % e)
ssl.SSLError: ("bad handshake: SysCallError(54, 'ECONNRESET')",)

During handling of the above exception, another exception occurred:

Traceback (most recent call last):
  File "/Library/Frameworks/Python.framework/Versions/3.7/lib/python3.7/site-packages/requests/adapters.py", line 449, in send
    timeout=timeout
  File "/Library/Frameworks/Python.framework/Versions/3.7/lib/python3.7/site-packages/urllib3/connectionpool.py", line 720, in urlopen
    method, url, error=e, _pool=self, _stacktrace=sys.exc_info()[2]
  File "/Library/Frameworks/Python.framework/Versions/3.7/lib/python3.7/site-packages/urllib3/util/retry.py", line 436, in increment
    raise MaxRetryError(_pool, url, error or ResponseError(cause))
urllib3.exceptions.MaxRetryError: HTTPSConnectionPool(host='raw.githubusercontent.com', port=443): Max retries exceeded with url: /Gius-8/COVID-19-JSON/master/csse_covid_19_daily_reports_json/07-21-2020.json (Caused by SSLError(SSLError("bad handshake: SysCallError(54, 'ECONNRESET')")))

During handling of the above exception, another exception occurred:

Traceback (most recent call last):
  File "covid19_data_retriever_PROD.py", line 230, in <module>
    gather_all_data("PROD")
  File "covid19_data_retriever_PROD.py", line 220, in gather_all_data
    gather_data_by_date(date, env)
  File "covid19_data_retriever_PROD.py", line 201, in gather_data_by_date
    date))
  File "/Library/Frameworks/Python.framework/Versions/3.7/lib/python3.7/site-packages/requests/api.py", line 75, in get
    return request('get', url, params=params, **kwargs)
  File "/Library/Frameworks/Python.framework/Versions/3.7/lib/python3.7/site-packages/requests/api.py", line 60, in request
    return session.request(method=method, url=url, **kwargs)
  File "/Library/Frameworks/Python.framework/Versions/3.7/lib/python3.7/site-packages/requests/sessions.py", line 533, in request
    resp = self.send(prep, **send_kwargs)
  File "/Library/Frameworks/Python.framework/Versions/3.7/lib/python3.7/site-packages/requests/sessions.py", line 646, in send
    r = adapter.send(request, **kwargs)
  File "/Library/Frameworks/Python.framework/Versions/3.7/lib/python3.7/site-packages/requests/adapters.py", line 514, in send
    raise SSLError(e, request=request)
requests.exceptions.SSLError: HTTPSConnectionPool(host='raw.githubusercontent.com', port=443): Max retries exceeded with url: /Gius-8/COVID-19-JSON/master/csse_covid_19_daily_reports_json/07-21-2020.json (Caused by SSLError(SSLError("bad handshake: SysCallError(54, 'ECONNRESET')")))
