No ISO: Others
No ISO: Cruise Ship
No ISO: Gambia, The
No ISO: Bahamas, The
No ISO: Cape Verde
No ISO: East Timor
No ISO: Syria
No ISO: Laos
No ISO: Diamond Princess
No ISO: West Bank and Gaza
No ISO: Burma
No ISO: MS Zaandam
Traceback (most recent call last):
  File "/Library/Frameworks/Python.framework/Versions/3.7/lib/python3.7/site-packages/urllib3/connectionpool.py", line 672, in urlopen
    chunked=chunked,
  File "/Library/Frameworks/Python.framework/Versions/3.7/lib/python3.7/site-packages/urllib3/connectionpool.py", line 421, in _make_request
    six.raise_from(e, None)
  File "<string>", line 3, in raise_from
  File "/Library/Frameworks/Python.framework/Versions/3.7/lib/python3.7/site-packages/urllib3/connectionpool.py", line 416, in _make_request
    httplib_response = conn.getresponse()
  File "/Library/Frameworks/Python.framework/Versions/3.7/lib/python3.7/http/client.py", line 1336, in getresponse
    response.begin()
  File "/Library/Frameworks/Python.framework/Versions/3.7/lib/python3.7/http/client.py", line 306, in begin
    version, status, reason = self._read_status()
  File "/Library/Frameworks/Python.framework/Versions/3.7/lib/python3.7/http/client.py", line 267, in _read_status
    line = str(self.fp.readline(_MAXLINE + 1), "iso-8859-1")
  File "/Library/Frameworks/Python.framework/Versions/3.7/lib/python3.7/socket.py", line 589, in readinto
    return self._sock.recv_into(b)
  File "/Library/Frameworks/Python.framework/Versions/3.7/lib/python3.7/site-packages/urllib3/contrib/pyopenssl.py", line 318, in recv_into
    raise SocketError(str(e))
OSError: (60, 'ETIMEDOUT')

During handling of the above exception, another exception occurred:

Traceback (most recent call last):
  File "/Library/Frameworks/Python.framework/Versions/3.7/lib/python3.7/site-packages/requests/adapters.py", line 449, in send
    timeout=timeout
  File "/Library/Frameworks/Python.framework/Versions/3.7/lib/python3.7/site-packages/urllib3/connectionpool.py", line 720, in urlopen
    method, url, error=e, _pool=self, _stacktrace=sys.exc_info()[2]
  File "/Library/Frameworks/Python.framework/Versions/3.7/lib/python3.7/site-packages/urllib3/util/retry.py", line 400, in increment
    raise six.reraise(type(error), error, _stacktrace)
  File "/Library/Frameworks/Python.framework/Versions/3.7/lib/python3.7/site-packages/urllib3/packages/six.py", line 734, in reraise
    raise value.with_traceback(tb)
  File "/Library/Frameworks/Python.framework/Versions/3.7/lib/python3.7/site-packages/urllib3/connectionpool.py", line 672, in urlopen
    chunked=chunked,
  File "/Library/Frameworks/Python.framework/Versions/3.7/lib/python3.7/site-packages/urllib3/connectionpool.py", line 421, in _make_request
    six.raise_from(e, None)
  File "<string>", line 3, in raise_from
  File "/Library/Frameworks/Python.framework/Versions/3.7/lib/python3.7/site-packages/urllib3/connectionpool.py", line 416, in _make_request
    httplib_response = conn.getresponse()
  File "/Library/Frameworks/Python.framework/Versions/3.7/lib/python3.7/http/client.py", line 1336, in getresponse
    response.begin()
  File "/Library/Frameworks/Python.framework/Versions/3.7/lib/python3.7/http/client.py", line 306, in begin
    version, status, reason = self._read_status()
  File "/Library/Frameworks/Python.framework/Versions/3.7/lib/python3.7/http/client.py", line 267, in _read_status
    line = str(self.fp.readline(_MAXLINE + 1), "iso-8859-1")
  File "/Library/Frameworks/Python.framework/Versions/3.7/lib/python3.7/socket.py", line 589, in readinto
    return self._sock.recv_into(b)
  File "/Library/Frameworks/Python.framework/Versions/3.7/lib/python3.7/site-packages/urllib3/contrib/pyopenssl.py", line 318, in recv_into
    raise SocketError(str(e))
urllib3.exceptions.ProtocolError: ('Connection aborted.', OSError("(60, 'ETIMEDOUT')"))

During handling of the above exception, another exception occurred:

Traceback (most recent call last):
  File "covid19_data_retriever_PROD.py", line 230, in <module>
    gather_all_data("PROD")
  File "covid19_data_retriever_PROD.py", line 220, in gather_all_data
    gather_data_by_date(date, env)
  File "covid19_data_retriever_PROD.py", line 201, in gather_data_by_date
    date))
  File "/Library/Frameworks/Python.framework/Versions/3.7/lib/python3.7/site-packages/requests/api.py", line 75, in get
    return request('get', url, params=params, **kwargs)
  File "/Library/Frameworks/Python.framework/Versions/3.7/lib/python3.7/site-packages/requests/api.py", line 60, in request
    return session.request(method=method, url=url, **kwargs)
  File "/Library/Frameworks/Python.framework/Versions/3.7/lib/python3.7/site-packages/requests/sessions.py", line 533, in request
    resp = self.send(prep, **send_kwargs)
  File "/Library/Frameworks/Python.framework/Versions/3.7/lib/python3.7/site-packages/requests/sessions.py", line 646, in send
    r = adapter.send(request, **kwargs)
  File "/Library/Frameworks/Python.framework/Versions/3.7/lib/python3.7/site-packages/requests/adapters.py", line 498, in send
    raise ConnectionError(err, request=request)
requests.exceptions.ConnectionError: ('Connection aborted.', OSError("(60, 'ETIMEDOUT')"))
